{"code":"ERR_HTTP_HEADERS_SENT","level":"error","message":"Cannot set headers after they are sent to the client Cannot set headers after they are sent to the client","stack":"Error [ERR_HTTP_HEADERS_SENT]: Cannot set headers after they are sent to the client\n    at ServerResponse.setHeader (node:_http_outgoing:652:11)\n    at ServerResponse.header (D:\\coding\\code_to_share\\shipGpt_front-end\\shipsaas\\server\\node_modules\\express\\lib\\response.js:794:10)\n    at ServerResponse.send (D:\\coding\\code_to_share\\shipGpt_front-end\\shipsaas\\server\\node_modules\\express\\lib\\response.js:174:12)\n    at ServerResponse.json (D:\\coding\\code_to_share\\shipGpt_front-end\\shipsaas\\server\\node_modules\\express\\lib\\response.js:278:15)\n    at loginCommonSection (D:\\coding\\code_to_share\\shipGpt_front-end\\shipsaas\\server\\controllers\\user-controller.js:160:19)\n    at process.processTicksAndRejections (node:internal/process/task_queues:95:5)"}
{"code":"ERR_HTTP_HEADERS_SENT","level":"error","message":"Cannot set headers after they are sent to the client Cannot set headers after they are sent to the client","stack":"Error [ERR_HTTP_HEADERS_SENT]: Cannot set headers after they are sent to the client\n    at ServerResponse.setHeader (node:_http_outgoing:652:11)\n    at ServerResponse.header (D:\\coding\\code_to_share\\shipGpt_front-end\\shipsaas\\server\\node_modules\\express\\lib\\response.js:794:10)\n    at ServerResponse.send (D:\\coding\\code_to_share\\shipGpt_front-end\\shipsaas\\server\\node_modules\\express\\lib\\response.js:174:12)\n    at ServerResponse.json (D:\\coding\\code_to_share\\shipGpt_front-end\\shipsaas\\server\\node_modules\\express\\lib\\response.js:278:15)\n    at loginCommonSection (D:\\coding\\code_to_share\\shipGpt_front-end\\shipsaas\\server\\controllers\\user-controller.js:162:19)\n    at process.processTicksAndRejections (node:internal/process/task_queues:95:5)"}
{"code":"ERR_UNHANDLED_REJECTION","level":"error","message":"This error originated either by throwing inside of an async function without a catch block, or by rejecting a promise which was not handled with .catch(). The promise rejected with the reason \"#<Object>\". This error originated either by throwing inside of an async function without a catch block, or by rejecting a promise which was not handled with .catch(). The promise rejected with the reason \"#<Object>\".","stack":"UnhandledPromiseRejection: This error originated either by throwing inside of an async function without a catch block, or by rejecting a promise which was not handled with .catch(). The promise rejected with the reason \"#<Object>\"."}
{"code":"ERR_UNHANDLED_REJECTION","level":"error","message":"This error originated either by throwing inside of an async function without a catch block, or by rejecting a promise which was not handled with .catch(). The promise rejected with the reason \"#<Object>\". This error originated either by throwing inside of an async function without a catch block, or by rejecting a promise which was not handled with .catch(). The promise rejected with the reason \"#<Object>\".","stack":"UnhandledPromiseRejection: This error originated either by throwing inside of an async function without a catch block, or by rejecting a promise which was not handled with .catch(). The promise rejected with the reason \"#<Object>\"."}
{"code":"ERR_HTTP_HEADERS_SENT","level":"error","message":"Cannot set headers after they are sent to the client Cannot set headers after they are sent to the client","stack":"Error [ERR_HTTP_HEADERS_SENT]: Cannot set headers after they are sent to the client\n    at ServerResponse.setHeader (node:_http_outgoing:699:11)\n    at ServerResponse.header (D:\\Company Code\\shipsaas\\server\\node_modules\\express\\lib\\response.js:795:10)\n    at ServerResponse.send (D:\\Company Code\\shipsaas\\server\\node_modules\\express\\lib\\response.js:175:12)\n    at ServerResponse.json (D:\\Company Code\\shipsaas\\server\\node_modules\\express\\lib\\response.js:279:15)\n    at Object.googleAuthCallBack (D:\\Company Code\\shipsaas\\server\\controllers\\auth_token-controller.js:12:8)\n    at process.processTicksAndRejections (node:internal/process/task_queues:105:5)"}
{"code":"ERR_UNHANDLED_REJECTION","level":"error","message":"This error originated either by throwing inside of an async function without a catch block, or by rejecting a promise which was not handled with .catch(). The promise rejected with the reason \"#<Object>\". This error originated either by throwing inside of an async function without a catch block, or by rejecting a promise which was not handled with .catch(). The promise rejected with the reason \"#<Object>\".","name":"UnhandledPromiseRejection","stack":"UnhandledPromiseRejection: This error originated either by throwing inside of an async function without a catch block, or by rejecting a promise which was not handled with .catch(). The promise rejected with the reason \"#<Object>\".\n    at throwUnhandledRejectionsMode (node:internal/process/promises:392:7)\n    at processPromiseRejections (node:internal/process/promises:475:17)\n    at process.processTicksAndRejections (node:internal/process/task_queues:106:32)"}
{"code":"ERR_UNHANDLED_REJECTION","level":"error","message":"This error originated either by throwing inside of an async function without a catch block, or by rejecting a promise which was not handled with .catch(). The promise rejected with the reason \"#<Object>\". This error originated either by throwing inside of an async function without a catch block, or by rejecting a promise which was not handled with .catch(). The promise rejected with the reason \"#<Object>\".","name":"UnhandledPromiseRejection","stack":"UnhandledPromiseRejection: This error originated either by throwing inside of an async function without a catch block, or by rejecting a promise which was not handled with .catch(). The promise rejected with the reason \"#<Object>\".\n    at throwUnhandledRejectionsMode (node:internal/process/promises:392:7)\n    at processPromiseRejections (node:internal/process/promises:475:17)\n    at process.processTicksAndRejections (node:internal/process/task_queues:106:32)"}
{"code":"ERR_UNHANDLED_REJECTION","level":"error","message":"This error originated either by throwing inside of an async function without a catch block, or by rejecting a promise which was not handled with .catch(). The promise rejected with the reason \"#<Object>\". This error originated either by throwing inside of an async function without a catch block, or by rejecting a promise which was not handled with .catch(). The promise rejected with the reason \"#<Object>\".","name":"UnhandledPromiseRejection","stack":"UnhandledPromiseRejection: This error originated either by throwing inside of an async function without a catch block, or by rejecting a promise which was not handled with .catch(). The promise rejected with the reason \"#<Object>\".\n    at throwUnhandledRejectionsMode (node:internal/process/promises:392:7)\n    at processPromiseRejections (node:internal/process/promises:475:17)\n    at process.processTicksAndRejections (node:internal/process/task_queues:106:32)"}
{"code":"ERR_UNHANDLED_REJECTION","level":"error","message":"This error originated either by throwing inside of an async function without a catch block, or by rejecting a promise which was not handled with .catch(). The promise rejected with the reason \"#<Object>\". This error originated either by throwing inside of an async function without a catch block, or by rejecting a promise which was not handled with .catch(). The promise rejected with the reason \"#<Object>\".","name":"UnhandledPromiseRejection","stack":"UnhandledPromiseRejection: This error originated either by throwing inside of an async function without a catch block, or by rejecting a promise which was not handled with .catch(). The promise rejected with the reason \"#<Object>\".\n    at throwUnhandledRejectionsMode (node:internal/process/promises:392:7)\n    at processPromiseRejections (node:internal/process/promises:475:17)\n    at process.processTicksAndRejections (node:internal/process/task_queues:106:32)"}
{"code":"ERR_UNHANDLED_REJECTION","level":"error","message":"This error originated either by throwing inside of an async function without a catch block, or by rejecting a promise which was not handled with .catch(). The promise rejected with the reason \"#<Object>\". This error originated either by throwing inside of an async function without a catch block, or by rejecting a promise which was not handled with .catch(). The promise rejected with the reason \"#<Object>\".","name":"UnhandledPromiseRejection","stack":"UnhandledPromiseRejection: This error originated either by throwing inside of an async function without a catch block, or by rejecting a promise which was not handled with .catch(). The promise rejected with the reason \"#<Object>\".\n    at throwUnhandledRejectionsMode (node:internal/process/promises:392:7)\n    at processPromiseRejections (node:internal/process/promises:475:17)\n    at process.processTicksAndRejections (node:internal/process/task_queues:106:32)"}
{"code":"ERR_UNHANDLED_REJECTION","level":"error","message":"This error originated either by throwing inside of an async function without a catch block, or by rejecting a promise which was not handled with .catch(). The promise rejected with the reason \"#<Object>\". This error originated either by throwing inside of an async function without a catch block, or by rejecting a promise which was not handled with .catch(). The promise rejected with the reason \"#<Object>\".","name":"UnhandledPromiseRejection","stack":"UnhandledPromiseRejection: This error originated either by throwing inside of an async function without a catch block, or by rejecting a promise which was not handled with .catch(). The promise rejected with the reason \"#<Object>\".\n    at throwUnhandledRejectionsMode (node:internal/process/promises:392:7)\n    at processPromiseRejections (node:internal/process/promises:475:17)\n    at process.processTicksAndRejections (node:internal/process/task_queues:106:32)"}
{"code":"ERR_UNHANDLED_REJECTION","level":"error","message":"This error originated either by throwing inside of an async function without a catch block, or by rejecting a promise which was not handled with .catch(). The promise rejected with the reason \"#<Object>\". This error originated either by throwing inside of an async function without a catch block, or by rejecting a promise which was not handled with .catch(). The promise rejected with the reason \"#<Object>\".","name":"UnhandledPromiseRejection","stack":"UnhandledPromiseRejection: This error originated either by throwing inside of an async function without a catch block, or by rejecting a promise which was not handled with .catch(). The promise rejected with the reason \"#<Object>\".\n    at throwUnhandledRejectionsMode (node:internal/process/promises:392:7)\n    at processPromiseRejections (node:internal/process/promises:475:17)\n    at process.processTicksAndRejections (node:internal/process/task_queues:106:32)"}
{"code":"ERR_UNHANDLED_REJECTION","level":"error","message":"This error originated either by throwing inside of an async function without a catch block, or by rejecting a promise which was not handled with .catch(). The promise rejected with the reason \"#<Object>\". This error originated either by throwing inside of an async function without a catch block, or by rejecting a promise which was not handled with .catch(). The promise rejected with the reason \"#<Object>\".","name":"UnhandledPromiseRejection","stack":"UnhandledPromiseRejection: This error originated either by throwing inside of an async function without a catch block, or by rejecting a promise which was not handled with .catch(). The promise rejected with the reason \"#<Object>\".\n    at throwUnhandledRejectionsMode (node:internal/process/promises:392:7)\n    at processPromiseRejections (node:internal/process/promises:475:17)\n    at process.processTicksAndRejections (node:internal/process/task_queues:106:32)"}
{"code":"ERR_UNHANDLED_REJECTION","level":"error","message":"This error originated either by throwing inside of an async function without a catch block, or by rejecting a promise which was not handled with .catch(). The promise rejected with the reason \"#<Object>\". This error originated either by throwing inside of an async function without a catch block, or by rejecting a promise which was not handled with .catch(). The promise rejected with the reason \"#<Object>\".","name":"UnhandledPromiseRejection","stack":"UnhandledPromiseRejection: This error originated either by throwing inside of an async function without a catch block, or by rejecting a promise which was not handled with .catch(). The promise rejected with the reason \"#<Object>\".\n    at throwUnhandledRejectionsMode (node:internal/process/promises:392:7)\n    at processPromiseRejections (node:internal/process/promises:475:17)\n    at process.processTicksAndRejections (node:internal/process/task_queues:106:32)"}
{"code":"ERR_UNHANDLED_REJECTION","level":"error","message":"This error originated either by throwing inside of an async function without a catch block, or by rejecting a promise which was not handled with .catch(). The promise rejected with the reason \"#<Object>\". This error originated either by throwing inside of an async function without a catch block, or by rejecting a promise which was not handled with .catch(). The promise rejected with the reason \"#<Object>\".","name":"UnhandledPromiseRejection","stack":"UnhandledPromiseRejection: This error originated either by throwing inside of an async function without a catch block, or by rejecting a promise which was not handled with .catch(). The promise rejected with the reason \"#<Object>\".\n    at throwUnhandledRejectionsMode (node:internal/process/promises:392:7)\n    at processPromiseRejections (node:internal/process/promises:475:17)\n    at process.processTicksAndRejections (node:internal/process/task_queues:106:32)"}
{"level":"error","message":"cb is not a function cb is not a function","stack":"TypeError: cb is not a function\n    at Query.onResult (D:\\Company Code\\shipsaas\\server\\passport\\index.js:45:18)\n    at PoolConnection._notifyError (D:\\Company Code\\shipsaas\\server\\node_modules\\mysql2\\lib\\connection.js:228:21)\n    at PoolConnection._handleFatalError (D:\\Company Code\\shipsaas\\server\\node_modules\\mysql2\\lib\\connection.js:183:10)\n    at PoolConnection.handlePacket (D:\\Company Code\\shipsaas\\server\\node_modules\\mysql2\\lib\\connection.js:491:12)\n    at PacketParser.onPacket (D:\\Company Code\\shipsaas\\server\\node_modules\\mysql2\\lib\\connection.js:97:12)\n    at PacketParser.executeStart (D:\\Company Code\\shipsaas\\server\\node_modules\\mysql2\\lib\\packet_parser.js:75:16)\n    at Socket.<anonymous> (D:\\Company Code\\shipsaas\\server\\node_modules\\mysql2\\lib\\connection.js:104:25)\n    at Socket.emit (node:events:524:28)\n    at addChunk (node:internal/streams/readable:561:12)\n    at readableAddChunkPushByteMode (node:internal/streams/readable:512:3)"}
{"level":"error","message":"cb is not a function cb is not a function","stack":"TypeError: cb is not a function\n    at Query.onResult (D:\\Company Code\\shipsaas\\server\\passport\\index.js:43:18)\n    at PoolConnection._notifyError (D:\\Company Code\\shipsaas\\server\\node_modules\\mysql2\\lib\\connection.js:228:21)\n    at PoolConnection._handleFatalError (D:\\Company Code\\shipsaas\\server\\node_modules\\mysql2\\lib\\connection.js:183:10)\n    at PoolConnection.handlePacket (D:\\Company Code\\shipsaas\\server\\node_modules\\mysql2\\lib\\connection.js:491:12)\n    at PacketParser.onPacket (D:\\Company Code\\shipsaas\\server\\node_modules\\mysql2\\lib\\connection.js:97:12)\n    at PacketParser.executeStart (D:\\Company Code\\shipsaas\\server\\node_modules\\mysql2\\lib\\packet_parser.js:75:16)\n    at Socket.<anonymous> (D:\\Company Code\\shipsaas\\server\\node_modules\\mysql2\\lib\\connection.js:104:25)\n    at Socket.emit (node:events:524:28)\n    at addChunk (node:internal/streams/readable:561:12)\n    at readableAddChunkPushByteMode (node:internal/streams/readable:512:3)"}
{"level":"error","message":"cb is not a function cb is not a function","stack":"TypeError: cb is not a function\n    at Query.onResult (D:\\Company Code\\shipsaas\\server\\passport\\index.js:45:18)\n    at PoolConnection._notifyError (D:\\Company Code\\shipsaas\\server\\node_modules\\mysql2\\lib\\connection.js:228:21)\n    at PoolConnection._handleFatalError (D:\\Company Code\\shipsaas\\server\\node_modules\\mysql2\\lib\\connection.js:183:10)\n    at PoolConnection.handlePacket (D:\\Company Code\\shipsaas\\server\\node_modules\\mysql2\\lib\\connection.js:491:12)\n    at PacketParser.onPacket (D:\\Company Code\\shipsaas\\server\\node_modules\\mysql2\\lib\\connection.js:97:12)\n    at PacketParser.executeStart (D:\\Company Code\\shipsaas\\server\\node_modules\\mysql2\\lib\\packet_parser.js:75:16)\n    at Socket.<anonymous> (D:\\Company Code\\shipsaas\\server\\node_modules\\mysql2\\lib\\connection.js:104:25)\n    at Socket.emit (node:events:524:28)\n    at addChunk (node:internal/streams/readable:561:12)\n    at readableAddChunkPushByteMode (node:internal/streams/readable:512:3)"}
{"level":"error","message":"cb is not a function cb is not a function","stack":"TypeError: cb is not a function\n    at Query.onResult (D:\\Company Code\\shipsaas\\server\\passport\\index.js:45:18)\n    at PoolConnection._notifyError (D:\\Company Code\\shipsaas\\server\\node_modules\\mysql2\\lib\\connection.js:228:21)\n    at PoolConnection._handleFatalError (D:\\Company Code\\shipsaas\\server\\node_modules\\mysql2\\lib\\connection.js:183:10)\n    at PoolConnection.handlePacket (D:\\Company Code\\shipsaas\\server\\node_modules\\mysql2\\lib\\connection.js:491:12)\n    at PacketParser.onPacket (D:\\Company Code\\shipsaas\\server\\node_modules\\mysql2\\lib\\connection.js:97:12)\n    at PacketParser.executeStart (D:\\Company Code\\shipsaas\\server\\node_modules\\mysql2\\lib\\packet_parser.js:75:16)\n    at Socket.<anonymous> (D:\\Company Code\\shipsaas\\server\\node_modules\\mysql2\\lib\\connection.js:104:25)\n    at Socket.emit (node:events:524:28)\n    at addChunk (node:internal/streams/readable:561:12)\n    at readableAddChunkPushByteMode (node:internal/streams/readable:512:3)"}
{"level":"error","message":"cb is not a function cb is not a function","stack":"TypeError: cb is not a function\n    at Query.onResult (D:\\Company Code\\shipsaas\\server\\passport\\index.js:45:18)\n    at PoolConnection._notifyError (D:\\Company Code\\shipsaas\\server\\node_modules\\mysql2\\lib\\connection.js:228:21)\n    at PoolConnection._handleFatalError (D:\\Company Code\\shipsaas\\server\\node_modules\\mysql2\\lib\\connection.js:183:10)\n    at PoolConnection.handlePacket (D:\\Company Code\\shipsaas\\server\\node_modules\\mysql2\\lib\\connection.js:491:12)\n    at PacketParser.onPacket (D:\\Company Code\\shipsaas\\server\\node_modules\\mysql2\\lib\\connection.js:97:12)\n    at PacketParser.executeStart (D:\\Company Code\\shipsaas\\server\\node_modules\\mysql2\\lib\\packet_parser.js:75:16)\n    at Socket.<anonymous> (D:\\Company Code\\shipsaas\\server\\node_modules\\mysql2\\lib\\connection.js:104:25)\n    at Socket.emit (node:events:524:28)\n    at addChunk (node:internal/streams/readable:561:12)\n    at readableAddChunkPushByteMode (node:internal/streams/readable:512:3)"}
{"level":"error","message":"You have tried to call .then(), .catch(), or invoked await on the result of query that is not a promise, which is a programming error. Try calling con.promise().query(), or require('mysql2/promise') instead of 'mysql2' for a promise-compatible version of the query interface. To learn how to use async/await or Promises check out documentation at https://sidorares.github.io/node-mysql2/docs#using-promise-wrapper, or the mysql2 documentation at https://sidorares.github.io/node-mysql2/docs/documentation/promise-wrapper You have tried to call .then(), .catch(), or invoked await on the result of query that is not a promise, which is a programming error. Try calling con.promise().query(), or require('mysql2/promise') instead of 'mysql2' for a promise-compatible version of the query interface. To learn how to use async/await or Promises check out documentation at https://sidorares.github.io/node-mysql2/docs#using-promise-wrapper, or the mysql2 documentation at https://sidorares.github.io/node-mysql2/docs/documentation/promise-wrapper","stack":"Error: You have tried to call .then(), .catch(), or invoked await on the result of query that is not a promise, which is a programming error. Try calling con.promise().query(), or require('mysql2/promise') instead of 'mysql2' for a promise-compatible version of the query interface. To learn how to use async/await or Promises check out documentation at https://sidorares.github.io/node-mysql2/docs#using-promise-wrapper, or the mysql2 documentation at https://sidorares.github.io/node-mysql2/docs/documentation/promise-wrapper\n    at Query.then (D:\\Company Code\\shipsaas\\server\\node_modules\\mysql2\\lib\\commands\\query.js:43:11)\n    at process.processTicksAndRejections (node:internal/process/task_queues:105:5)"}
{"level":"error","message":"You have tried to call .then(), .catch(), or invoked await on the result of query that is not a promise, which is a programming error. Try calling con.promise().query(), or require('mysql2/promise') instead of 'mysql2' for a promise-compatible version of the query interface. To learn how to use async/await or Promises check out documentation at https://sidorares.github.io/node-mysql2/docs#using-promise-wrapper, or the mysql2 documentation at https://sidorares.github.io/node-mysql2/docs/documentation/promise-wrapper You have tried to call .then(), .catch(), or invoked await on the result of query that is not a promise, which is a programming error. Try calling con.promise().query(), or require('mysql2/promise') instead of 'mysql2' for a promise-compatible version of the query interface. To learn how to use async/await or Promises check out documentation at https://sidorares.github.io/node-mysql2/docs#using-promise-wrapper, or the mysql2 documentation at https://sidorares.github.io/node-mysql2/docs/documentation/promise-wrapper","stack":"Error: You have tried to call .then(), .catch(), or invoked await on the result of query that is not a promise, which is a programming error. Try calling con.promise().query(), or require('mysql2/promise') instead of 'mysql2' for a promise-compatible version of the query interface. To learn how to use async/await or Promises check out documentation at https://sidorares.github.io/node-mysql2/docs#using-promise-wrapper, or the mysql2 documentation at https://sidorares.github.io/node-mysql2/docs/documentation/promise-wrapper\n    at Query.then (D:\\Company Code\\shipsaas\\server\\node_modules\\mysql2\\lib\\commands\\query.js:43:11)\n    at process.processTicksAndRejections (node:internal/process/task_queues:105:5)"}
{"level":"error","message":"You have tried to call .then(), .catch(), or invoked await on the result of query that is not a promise, which is a programming error. Try calling con.promise().query(), or require('mysql2/promise') instead of 'mysql2' for a promise-compatible version of the query interface. To learn how to use async/await or Promises check out documentation at https://sidorares.github.io/node-mysql2/docs#using-promise-wrapper, or the mysql2 documentation at https://sidorares.github.io/node-mysql2/docs/documentation/promise-wrapper You have tried to call .then(), .catch(), or invoked await on the result of query that is not a promise, which is a programming error. Try calling con.promise().query(), or require('mysql2/promise') instead of 'mysql2' for a promise-compatible version of the query interface. To learn how to use async/await or Promises check out documentation at https://sidorares.github.io/node-mysql2/docs#using-promise-wrapper, or the mysql2 documentation at https://sidorares.github.io/node-mysql2/docs/documentation/promise-wrapper","stack":"Error: You have tried to call .then(), .catch(), or invoked await on the result of query that is not a promise, which is a programming error. Try calling con.promise().query(), or require('mysql2/promise') instead of 'mysql2' for a promise-compatible version of the query interface. To learn how to use async/await or Promises check out documentation at https://sidorares.github.io/node-mysql2/docs#using-promise-wrapper, or the mysql2 documentation at https://sidorares.github.io/node-mysql2/docs/documentation/promise-wrapper\n    at Query.then (D:\\Company Code\\shipsaas\\server\\node_modules\\mysql2\\lib\\commands\\query.js:43:11)\n    at process.processTicksAndRejections (node:internal/process/task_queues:105:5)"}
